{"channel":"book","type":"snapshot","data":[{"symbol":"SOL/USD","bids":[{"price":120.56,"qty":104.69591278},{"price":120.55,"qty":171.25678823},{"price":120.54,"qty":677.51180647},{"price":120.53,"qty":81.67168962},{"price":120.52,"qty":212.40451408},{"price":120.51,"qty":445.32541027},{"price":120.50,"qty":216.65600934},{"price":120.49,"qty":574.51158297},{"price":120.48,"qty":222.49567504},{"price":120.47,"qty":492.71109901},{"price":120.46,"qty":1971.11026667},{"price":120.45,"qty":340.38844768},{"price":120.44,"qty":145.11906145},{"price":120.43,"qty":675.44411348},{"price":120.42,"qty":123.94758635},{"price":120.41,"qty":415.23479513},{"price":120.40,"qty":2555.72424214},{"price":120.39,"qty":247.19663027},{"price":120.38,"qty":415.33709255},{"price":120.37,"qty":176.62743107},{"price":120.36,"qty":416.33741963},{"price":120.35,"qty":29.60787556},{"price":120.34,"qty":1934.19616459},{"price":120.33,"qty":2337.74180177},{"price":120.32,"qty":10513.15049289},{"price":120.31,"qty":129.47010535},{"price":120.30,"qty":35.75020781},{"price":120.29,"qty":88.99760555},{"price":120.28,"qty":10.00000000},{"price":120.27,"qty":71.37219441},{"price":120.25,"qty":2.89589343},{"price":120.24,"qty":60.06163424},{"price":120.23,"qty":2481.08798842},{"price":120.22,"qty":593.22119362},{"price":120.21,"qty":29.66960752},{"price":120.20,"qty":260.56150475},{"price":120.19,"qty":0.06157627},{"price":120.18,"qty":0.18156873},{"price":120.17,"qty":20.92792615},{"price":120.16,"qty":33.78258313}],"asks":[{"price":120.58,"qty":122.85820127},{"price":120.59,"qty":7.92388712},{"price":120.60,"qty":87.22689440},{"price":120.61,"qty":69.43530325},{"price":120.62,"qty":106.22108926},{"price":120.63,"qty":454.27258485},{"price":120.64,"qty":273.56879092},{"price":120.65,"qty":88.55027194},{"price":120.66,"qty":1048.95410489},{"price":120.67,"qty":503.37420119},{"price":120.68,"qty":2119.32862397},{"price":120.69,"qty":456.37992879},{"price":120.70,"qty":130.32196857},{"price":120.71,"qty":436.62971791},{"price":120.72,"qty":604.98207938},{"price":120.73,"qty":559.53038992},{"price":120.74,"qty":1512.20177947},{"price":120.75,"qty":868.78627200},{"price":120.76,"qty":260.34310259},{"price":120.77,"qty":2074.40048224},{"price":120.78,"qty":43.17995542},{"price":120.79,"qty":52.17465572},{"price":120.80,"qty":30.57113705},{"price":120.81,"qty":477.99446233},{"price":120.82,"qty":0.06163384},{"price":120.83,"qty":10344.97979449},{"price":120.84,"qty":2462.69856139},{"price":120.85,"qty":0.06150682},{"price":120.86,"qty":260.34311996},{"price":120.87,"qty":454.53030931},{"price":120.88,"qty":421.21607171},{"price":120.91,"qty":261.95044077},{"price":120.93,"qty":3.25176275},{"price":120.94,"qty":744.66440517},{"price":120.97,"qty":20.72000000},{"price":121.00,"qty":36.84358210},{"price":121.01,"qty":840.53742700},{"price":121.02,"qty":1012.58355539},{"price":121.03,"qty":826.30207878},{"price":121.04,"qty":0.06137794}],"checksum":2351393400,"timestamp":"2026-09-26T04:42:53.095223Z"}]}
{"channel":"book","type":"update","data":[{"symbol":"SOL/USD","bids":[{"price":120.40,"qty":539.11731086}],"asks":[],"checksum":2351393400,"timestamp":"2026-09-26T04:42:53.117617Z"}]}
{"channel":"book","type":"update","data":[{"symbol":"SOL/USD","bids":[{"price":120.47,"qty":2509.31803029}],"asks":[],"checksum":498323887,"timestamp":"2026-09-26T04:42:53.117617Z"}]}
{"channel":"book","type":"update","data":[{"symbol":"SOL/USD","bids":[],"asks":[{"price":120.75,"qty":833.49772857}],"checksum":498323887,"timestamp":"2026-09-26T04:42:53.123462Z"}]}
{"channel":"book","type":"update","data":[{"symbol":"SOL/USD","bids":[],"asks":[{"price":120.59,"qty":31.22381929}],"checksum":29545798,"timestamp":"2026-09-26T04:42:53.124154Z"}]}
{"channel":"book","type":"update","data":[{"symbol":"SOL/USD","bids":[],"asks":[{"price":120.87,"qty":413.75297055}],"checksum":29545798,"timestamp":"2026-09-26T04:42:53.176389Z"}]}
{"channel":"book","type":"update","data":[{"symbol":"SOL/USD","bids":[],"asks":[{"price":120.86,"qty":301.12302194}],"checksum":29545798,"timestamp":"2026-09-26T04:42:53.176389Z"}]}
{"channel":"book","type":"update","data":[{"symbol":"SOL/USD","bids":[{"price":120.54,"qty":607.00970032}],"asks":[],"checksum":3179573690,"timestamp":"2026-09-26T04:42:53.177275Z"}]}
{"channel":"book","type":"update","data":[{"symbol":"SOL/USD","bids":[{"price":120.48,"qty":292.99778119}],"asks":[],"checksum":1654677340,"timestamp":"2026-09-26T04:42:53.177275Z"}]}
{"channel":"book","type":"update","data":[{"symbol":"SOL/USD","bids":[{"price":120.54,"qty":304.51866064}],"asks":[],"checksum":2675311657,"timestamp":"2026-09-26T04:42:53.279786Z"}]}
{"channel":"book","type":"update","data":[{"symbol":"SOL/USD","bids":[{"price":120.53,"qty":384.16272930}],"asks":[],"checksum":2529766238,"timestamp":"2026-09-26T04:42:53.279786Z"}]}
{"channel":"book","type":"update","data":[{"symbol":"SOL/USD","bids":[{"price":120.55,"qty":23.18989398}],"asks":[],"checksum":365847776,"timestamp":"2026-09-26T04:42:53.280612Z"}]}
{"channel":"book","type":"update","data":[{"symbol":"SOL/USD","bids":[{"price":120.55,"qty":75.66545923}],"asks":[],"checksum":2568205,"timestamp":"2026-09-26T04:42:53.281238Z"}]}
{"channel":"book","type":"update","data":[{"symbol":"SOL/USD","bids":[{"price":120.36,"qty":415.40441963}],"asks":[],"checksum":2568205,"timestamp":"2026-09-26T04:42:53.297769Z"}]}
{"channel":"book","type":"update","data":[{"symbol":"SOL/USD","bids":[{"price":120.37,"qty":177.56043107}],"asks":[],"checksum":2568205,"timestamp":"2026-09-26T04:42:53.299407Z"}]}
{"channel":"book","type":"update","data":[{"symbol":"SOL/USD","bids":[{"price":120.53,"qty":81.67168962}],"asks":[],"checksum":2026232163,"timestamp":"2026-09-26T04:42:53.311865Z"}]}
{"channel":"book","type":"update","data":[{"symbol":"SOL/USD","bids":[{"price":120.54,"qty":607.00970032}],"asks":[],"checksum":2232648214,"timestamp":"2026-09-26T04:42:53.311865Z"}]}
{"channel":"book","type":"update","data":[{"symbol":"SOL/USD","bids":[],"asks":[{"price":120.79,"qty":0.06198088}],"checksum":2232648214,"timestamp":"2026-09-26T04:42:53.445408Z"}]}
{"channel":"book","type":"update","data":[{"symbol":"SOL/USD","bids":[],"asks":[{"price":120.82,"qty":52.17430868}],"checksum":2232648214,"timestamp":"2026-09-26T04:42:53.445408Z"}]}
{"channel":"book","type":"update","data":[{"symbol":"SOL/USD","bids":[{"price":120.49,"qty":504.00947682}],"asks":[],"checksum":3883154479,"timestamp":"2026-09-26T04:42:53.446008Z"}]}
{"channel":"book","type":"update","data":[{"symbol":"SOL/USD","bids":[{"price":120.57,"qty":26.17397820}],"asks":[],"checksum":924381945,"timestamp":"2026-09-26T04:42:53.446008Z"}]}
{"channel":"book","type":"update","data":[{"symbol":"SOL/USD","bids":[{"price":120.37,"qty":131.71140537}],"asks":[],"checksum":924381945,"timestamp":"2026-09-26T04:42:53.447081Z"}]}
{"channel":"book","type":"update","data":[{"symbol":"SOL/USD","bids":[{"price":120.38,"qty":461.18611825}],"asks":[],"checksum":924381945,"timestamp":"2026-09-26T04:42:53.447081Z"}]}
{"channel":"book","type":"update","data":[{"symbol":"SOL/USD","bids":[{"price":120.56,"qty":90.95634021}],"asks":[],"checksum":2551201515,"timestamp":"2026-09-26T04:42:53.448230Z"}]}
{"channel":"book","type":"update","data":[{"symbol":"SOL/USD","bids":[{"price":108.51,"qty":13.73957257}],"asks":[],"checksum":2551201515,"timestamp":"2026-09-26T04:42:53.448230Z"}]}
{"channel":"book","type":"update","data":[{"symbol":"SOL/USD","bids":[],"asks":[{"price":120.63,"qty":487.79076671}],"checksum":2816049974,"timestamp":"2026-09-26T04:42:53.497647Z"}]}
{"channel":"book","type":"update","data":[{"symbol":"SOL/USD","bids":[{"price":120.54,"qty":304.51866064}],"asks":[],"checksum":945636431,"timestamp":"2026-09-26T04:42:53.517897Z"}]}
{"channel":"book","type":"update","data":[{"symbol":"SOL/USD","bids":[{"price":120.53,"qty":384.16272930}],"asks":[],"checksum":941493154,"timestamp":"2026-09-26T04:42:53.517897Z"}]}
{"channel":"book","type":"update","data":[{"symbol":"SOL/USD","bids":[],"asks":[{"price":120.62,"qty":106.10998171}],"checksum":2964086953,"timestamp":"2026-09-26T04:42:53.544582Z"}]}
{"channel":"book","type":"update","data":[{"symbol":"SOL/USD","bids":[],"asks":[{"price":120.86,"qty":260.34311996}],"checksum":2964086953,"timestamp":"2026-09-26T04:42:53.571080Z"}]}
{"channel":"book","type":"update","data":[{"symbol":"SOL/USD","bids":[],"asks":[{"price":120.87,"qty":454.53355684}],"checksum":2964086953,"timestamp":"2026-09-26T04:42:53.571080Z"}]}
{"channel":"book","type":"update","data":[{"symbol":"SOL/USD","bids":[{"price":120.53,"qty":81.67168962}],"asks":[],"checksum":2188159383,"timestamp":"2026-09-26T04:42:53.617741Z"}]}
{"channel":"book","type":"update","data":[{"symbol":"SOL/USD","bids":[{"price":120.54,"qty":607.00970032}],"asks":[],"checksum":501772014,"timestamp":"2026-09-26T04:42:53.617741Z"}]}
{"channel":"book","type":"update","data":[{"symbol":"SOL/USD","bids":[],"asks":[{"price":120.71,"qty":472.18710672}],"checksum":501772014,"timestamp":"2026-09-26T04:42:53.623380Z"}]}
{"channel":"book","type":"update","data":[{"symbol":"SOL/USD","bids":[],"asks":[{"price":120.62,"qty":106.22108950}],"checksum":336373451,"timestamp":"2026-09-26T04:42:53.757395Z"}]}
{"channel":"book","type":"update","data":[{"symbol":"SOL/USD","bids":[{"price":120.48,"qty":222.49567504}],"asks":[],"checksum":1065432352,"timestamp":"2026-09-26T04:42:53.757993Z"}]}
{"channel":"book","type":"update","data":[{"symbol":"SOL/USD","bids":[{"price":120.55,"qty":146.16756538}],"asks":[],"checksum":2215678835,"timestamp":"2026-09-26T04:42:53.757993Z"}]}
{"channel":"book","type":"update","data":[{"symbol":"SOL/USD","bids":[{"price":120.47,"qty":492.71109901}],"asks":[],"checksum":2215678835,"timestamp":"2026-09-26T04:42:53.795983Z"}]}
{"channel":"book","type":"update","data":[{"symbol":"SOL/USD","bids":[{"price":120.35,"qty":2046.21480684}],"asks":[],"checksum":2215678835,"timestamp":"2026-09-26T04:42:53.795983Z"}]}
{"channel":"book","type":"update","data":[{"symbol":"SOL/USD","bids":[],"asks":[{"price":120.58,"qty":122.39747313}],"checksum":1669997285,"timestamp":"2026-09-26T04:42:53.809082Z"}]}
{"channel":"book","type":"update","data":[{"symbol":"SOL/USD","bids":[{"price":120.54,"qty":304.51866064}],"asks":[],"checksum":4228834716,"timestamp":"2026-09-26T04:42:53.879508Z"}]}
{"channel":"book","type":"update","data":[{"symbol":"SOL/USD","bids":[{"price":120.53,"qty":384.16272930}],"asks":[],"checksum":998178533,"timestamp":"2026-09-26T04:42:53.879508Z"}]}
{"channel":"book","type":"update","data":[{"symbol":"SOL/USD","bids":[{"price":120.39,"qty":242.87383082}],"asks":[],"checksum":998178533,"timestamp":"2026-09-26T04:42:53.888883Z"}]}
{"channel":"book","type":"update","data":[{"symbol":"SOL/USD","bids":[],"asks":[{"price":121.41,"qty":0.00000000},{"price":163.71,"qty":0.07790000}],"checksum":998178533,"timestamp":"2026-09-26T04:42:53.900530Z"}]}
{"channel":"book","type":"update","data":[{"symbol":"SOL/USD","bids":[],"asks":[{"price":121.40,"qty":603.07741416}],"checksum":998178533,"timestamp":"2026-09-26T04:42:53.900530Z"}]}
{"channel":"book","type":"update","data":[{"symbol":"SOL/USD","bids":[],"asks":[{"price":120.87,"qty":413.75297055}],"checksum":998178533,"timestamp":"2026-09-26T04:42:53.965975Z"}]}
{"channel":"book","type":"update","data":[{"symbol":"SOL/USD","bids":[],"asks":[{"price":120.86,"qty":301.12138522}],"checksum":998178533,"timestamp":"2026-09-26T04:42:53.965975Z"}]}
{"channel":"book","type":"update","data":[{"symbol":"SOL/USD","bids":[{"price":120.54,"qty":102.85796752}],"asks":[],"checksum":689737101,"timestamp":"2026-09-26T04:42:54.017845Z"}]}
{"channel":"book","type":"update","data":[{"symbol":"SOL/USD","bids":[{"price":120.52,"qty":414.06520720}],"asks":[],"checksum":218919192,"timestamp":"2026-09-26T04:42:54.017845Z"}]}
{"channel":"book","type":"update","data":[{"symbol":"SOL/USD","bids":[{"price":120.55,"qty":93.69200013}],"asks":[],"checksum":1755139330,"timestamp":"2026-09-26T04:42:54.018470Z"}]}
{"channel":"book","type":"update","data":[{"symbol":"SOL/USD","bids":[{"price":120.56,"qty":112.00121890}],"asks":[],"checksum":1371447414,"timestamp":"2026-09-26T04:42:54.019129Z"}]}
{"channel":"book","type":"update","data":[{"symbol":"SOL/USD","bids":[{"price":120.41,"qty":419.55823894}],"asks":[],"checksum":1371447414,"timestamp":"2026-09-26T04:42:54.118266Z"}]}
{"channel":"book","type":"update","data":[{"symbol":"SOL/USD","bids":[],"asks":[{"price":121.14,"qty":97.37659652}],"checksum":1371447414,"timestamp":"2026-09-26T04:42:54.227968Z"}]}
{"channel":"book","type":"update","data":[{"symbol":"SOL/USD","bids":[],"asks":[{"price":121.13,"qty":659.04474580}],"checksum":1371447414,"timestamp":"2026-09-26T04:42:54.227968Z"}]}
{"channel":"book","type":"update","data":[{"symbol":"SOL/USD","bids":[{"price":120.27,"qty":9.38340000}],"asks":[],"checksum":1371447414,"timestamp":"2026-09-26T04:42:54.489471Z"}]}
{"channel":"book","type":"update","data":[{"symbol":"SOL/USD","bids":[{"price":120.28,"qty":71.97596549}],"asks":[],"checksum":1371447414,"timestamp":"2026-09-26T04:42:54.489471Z"}]}
{"channel":"book","type":"update","data":[{"symbol":"SOL/USD","bids":[{"price":120.55,"qty":23.18989398}],"asks":[],"checksum":983514181,"timestamp":"2026-09-26T04:42:54.490334Z"}]}
{"channel":"book","type":"update","data":[{"symbol":"SOL/USD","bids":[{"price":120.54,"qty":173.36007367}],"asks":[],"checksum":1098315412,"timestamp":"2026-09-26T04:42:54.490334Z"}]}
{"channel":"book","type":"update","data":[{"symbol":"SOL/USD","bids":[{"price":120.56,"qty":90.95634021}],"asks":[],"checksum":2018843616,"timestamp":"2026-09-26T04:42:54.490908Z"}]}
{"channel":"book","type":"update","data":[{"symbol":"SOL/USD","bids":[{"price":120.34,"qty":1134.19616459}],"asks":[],"checksum":2018843616,"timestamp":"2026-09-26T04:42:54.609477Z"}]}
{"channel":"book","type":"update","data":[{"symbol":"SOL/USD","bids":[{"price":120.36,"qty":1215.40441963}],"asks":[],"checksum":2018843616,"timestamp":"2026-09-26T04:42:54.609477Z"}]}
